#VRML_SIM R2025a utf8

EXTERNPROTO "https://raw.githubusercontent.com/cyberbotics/webots/4bcca6b05171cae3700640495447d49abc506ed3/projects/objects/backgrounds/protos/TexturedBackground.proto"
EXTERNPROTO "https://raw.githubusercontent.com/cyberbotics/webots/4bcca6b05171cae3700640495447d49abc506ed3/projects/objects/backgrounds/protos/TexturedBackgroundLight.proto"
EXTERNPROTO "https://raw.githubusercontent.com/cyberbotics/webots/R2022b/projects/objects/floors/protos/CircleArena.proto"

WorldInfo {
}
Viewpoint {
  orientation -0.33185733874619844 -0.09874274160469809 0.9381474178937331 3.686018050088086
  position 1.700313773507203 1.0549607538959629 1.4846240848267684
  follow "car"
}
TexturedBackground {
}
TexturedBackgroundLight {
}
CircleArena {
}
Robot {
  children [
    DEF body Pose {
      translation 0 0 0.0415
      children [
        Shape {
          appearance PBRAppearance {
            baseColor 1 0 0
            roughness 0.8
            metalness 0.2
          }
          geometry Box {
            size 0.2 0.08 0.1
          }
        }
      ]
    }
    HingeJoint {
      jointParameters HingeJointParameters {
        anchor 0.1 0.045 0.0125
        axis 0 1 0
      }
      device [
        RotationalMotor {
          name "front left"
        }
      ]
      endPoint Solid {
        translation 0.1 0.045 0.0125
        rotation 1 0 0 1.57
        children [
          DEF wheel Shape {
            appearance PBRAppearance {
              baseColor 0 0 0
              roughness 0.65
              metalness 0.35
            }
            geometry Cylinder {
              height 0.01
              radius 0.025
            }
          }
        ]
        boundingObject USE wheel
        physics DEF wheel_physics Physics {
        }
      }
    }
    HingeJoint {
      jointParameters HingeJointParameters {
        anchor 0.1 -0.045 0.0125
        axis 0 1 0
      }
      device [
        RotationalMotor {
          name "front right"
        }
      ]
      endPoint Solid {
        translation 0.1 -0.045 0.0125
        rotation 1 0 0 1.57
        children [
          USE wheel
        ]
        name "solid(1)"
        boundingObject USE wheel
        physics USE wheel_physics
      }
    }
    HingeJoint {
      jointParameters HingeJointParameters {
        anchor -0.1 -0.045 0.0125
        axis 0 1 0
      }
      device [
        RotationalMotor {
          name "back right"
        }
      ]
      endPoint Solid {
        translation -0.1 -0.045 0.0125
        rotation 1 0 0 1.57
        children [
          USE wheel
        ]
        name "solid(2)"
        boundingObject USE wheel
        physics USE wheel_physics
      }
    }
    HingeJoint {
      jointParameters HingeJointParameters {
        anchor -0.1 0.045 0.0125
        axis 0 1 0
      }
      device [
        RotationalMotor {
          name "back left"
        }
      ]
      endPoint Solid {
        translation -0.1 0.045 0.0125
        rotation 1 0 0 1.57
        children [
          USE wheel
        ]
        name "solid(3)"
        boundingObject USE wheel
        physics USE wheel_physics
      }
    }
    DistanceSensor {
      translation 0.1 0.03 0.06
      rotation 0 0 1 0
      children [
        DEF sensor Pose {
          rotation 0 0 1 1.57
          children [
            Shape {
              appearance PBRAppearance {
                baseColor 1 1 0
                roughness 1
                metalness 0
              }
              geometry Cylinder {
                height 0.004
                radius 0.008
              }
            }
          ]
        }
      ]
      name "ds0"
      lookupTable [
        0 1020 0
        0.15 510 0
        0.3 0 0
      ]
      numberOfRays 2
      aperture 1
    }
    DistanceSensor {
      translation 0.1 -0.03 0.06
      rotation 0 0 1 0
      children [
        USE sensor
      ]
      name "ds1"
      lookupTable [
        0 1020 0
        0.15 510 0
        0.3 0 0
      ]
      numberOfRays 2
      aperture 1
    }
  ]
  name "car"
  controller "<extern>"
  boundingObject USE body
  physics Physics {
  }
}
